<?xml version="1.0" ?>
<sdf version="1.6">
  <model name="entrance_door">
    <static>false</static>
    <link name="door_post">
      <pose>0 -0.5 1 0 0 0</pose> 
      <inertial>
        <mass>1.0</mass>
        <inertia ixx="0.01" ixy="0" ixz="0" iyy="0.01" iyz="0" izz="0.01" />
      </inertial>
      <visual name="visual">
        <geometry><box><size>0.05 0.1 2.0</size></box></geometry>
        <material><ambient>0.8 0.4 0.1 1</ambient></material>
      </visual>
    </link>

    <link name="door_leaf">
      <pose>0 0 1 0 0 0</pose> 
      <inertial>
        <mass>5.0</mass>
        <inertia ixx="0.01" ixy="0" ixz="0" iyy="0.01" iyz="0" izz="0.01" />
      </inertial>
      <visual name="visual">
        <geometry><box><size>0.05 1.0 2.0</size></box></geometry>
        <material><ambient>0.8 0.4 0.1 1</ambient></material>
      </visual>
      <collision name="collision">
        <geometry><box><size>0.05 1.0 2.0</size></box></geometry>
      </collision>
    </link>

    <joint name="door_joint" type="revolute">
      <parent>door_post</parent>
      <child>door_leaf</child>
      <pose>0 0.5 0 0 0 0</pose> 
      <axis>
        <xyz>0 0 1</xyz> 
        <limit lower="-1.57" upper="0"/> 
      </axis>
    </joint>

  </model>
</sdf>
